Workbook

Sheet Summary
A1: Test | B1: Condition | C1: IAE | D1: ISE | E1: A→B Overshoot (%) | F1: A→B Fall Time (s) | G1: B→A Overshoot (%) | H1: B→A Rise Time (s)
A2: Baseline | B2: Clean | C2: =sensor_log_baseline!S4 -> 86.022033 | D2: =sensor_log_baseline!S5 -> 456.83424 | E2: =sensor_log_baseline!S11 -> 17.269039 | F2: =sensor_log_baseline!S13 -> 1.2548101 | G2: =sensor_log_baseline!S24 -> 14.849102 | H2: =sensor_log_baseline!S26 -> 6.3232801
B3: TC | C3: =sensor_log_baseline_tc!S4 -> 93.833179 | D3: =sensor_log_baseline_tc!S5 -> 561.79674 | E3: =sensor_log_baseline_tc!S11 -> 33.351962 | F3: =sensor_log_baseline_tc!S13 -> 1.4051402 | G3: =sensor_log_baseline_tc!S24 -> 11.332667 | H3: =sensor_log_baseline_tc!S26 -> 3.4122598
A5: CPU Stress | B5: Degraded | C5: =sensor_log_cpu!S4 -> 110.52882 | D5: =sensor_log_cpu!S5 -> 749.88803 | E5: =sensor_log_cpu!S12 -> 8.0145439 | F5: =sensor_log_cpu!S15 -> 2.3075202 | G5: =sensor_log_cpu!S27 -> 1.8873572 | H5: =sensor_log_cpu!S30 -> 7.8306899
B6: TC | C6: =sensor_log_cpu_tc!S5 -> 93.003131 | D6: =sensor_log_cpu_tc!S6 -> 587.16069 | E6: =sensor_log_cpu_tc!S12 -> 11.490091 | F6: =sensor_log_cpu_tc!S14 -> 1.6550601 | G6: =sensor_log_cpu_tc!S25 -> 28.035736 | H6: =sensor_log_cpu_tc!S27 -> 4.9150701
A8: Iperf Stress | B8: Degraded | C8: =sensor_log_iperf!S5 -> 259.7695 | D8: =sensor_log_iperf!S6 -> 2880.521 | E8: =sensor_log_iperf!S13 -> 51.60199 | F8: =sensor_log_iperf!S16 -> 2.8110001 | G8: =sensor_log_iperf!S28 -> 34.598386 | H8: =sensor_log_iperf!S31 -> 3.61255
B9: TC | C9: =sensor_log_iperf_tc!S5 -> 73.664053 | D9: =sensor_log_iperf_tc!S6 -> 411.3435 | E9: =sensor_log_iperf_tc!S12 -> 13.725344 | F9: =sensor_log_iperf_tc!S14 -> 1.6561501 | G9: =sensor_log_iperf_tc!S25 -> 5.2811265 | H9: =sensor_log_iperf_tc!S27 -> 2.4583499

Sheet sensor_log_baseline
A1: timestamp | B1: distance | C1: setpoint | D1: duty | E1: delay_ms | F1: loss_rate | G1: osc_a | H1: osc_b | I1: osc_period | J1: next_setpoint | K1: switch_in | L1: pid_status | M1: Time Step (dt) | N1: Error (E) | O1: |E| * dt | P1: E^2 * dt
A2: 1.7646154e+09 | B2: 45.664597 | C2: 20 | D2: 0 | E2: 0 | F2: 0 | G2: 20 | H2: 30 | I2: 20 | J2: 30 | K2: 0 | L2: STOPPED | M2: (Time Between Samples) | N2: (Instantaneous Tracking Error) | O2: (Instantaneous Area under the Absolute Error Curve) | P2: (Instantaneous Area under the Squared Error Curve) | R2: SUM dt | S2: =SUM(M440:M1236) -> 39.9953 | T2: Only sum during oscillation periods
A3: 1.7646154e+09 | B3: 45.566463 | C3: 20 | D3: 0 | E3: 0 | F3: 0 | G3: 20 | H3: 30 | I3: 20 | J3: 30 | K3: 0 | L3: STOPPED | M3: =A3-A2 -> 0.047379971 | N3: =C3-B3 -> -25.566463 | O3: =ABS(N3)*M3 -> 1.2113383 | P3: =N3^2 * M3 -> 30.969636 | Q3: =IF(C3<>C2, "OSCILLATION", "--") -> -- | R3: SUM E | S3: =SUM(N440:N1236) -> -1038.5778
A4: 1.7646154e+09 | B4: 45.300686 | C4: 20 | D4: 0 | E4: 0 | F4: 0 | G4: 20 | H4: 30 | I4: 20 | J4: 30 | K4: 0 | L4: STOPPED | M4: =A4-A3 -> 0.051009893 | N4: =C4-B4 -> -25.300686 | O4: =ABS(N4)*M4 -> 1.2905853 | P4: =N4^2 * M4 -> 32.652694 | Q4: =IF(C4<>C3, "OSCILLATION", "--") -> -- | R4: ="SUM "&O1 -> SUM |E| * dt | S4: =SUM(O440:O1236) -> 86.022033 | T4: Total Integral Absolute Error (IAE)
A5: 1.7646154e+09 | B5: 45.631886 | C5: 20 | D5: 0 | E5: 0 | F5: 0 | G5: 20 | H5: 30 | I5: 20 | J5: 30 | K5: 0 | L5: STOPPED | M5: =A5-A4 -> 0.050420046 | N5: =C5-B5 -> -25.631886 | O5: =ABS(N5)*M5 -> 1.2923608 | P5: =N5^2 * M5 -> 33.125645 | Q5: =IF(C5<>C4, "OSCILLATION", "--") -> -- | R5: ="SUM "&P1 -> SUM E^2 * dt | S5: =SUM(P440:P1236) -> 456.83424 | T5: Total Integral Squared Error (ISE)
A6: 1.7646154e+09 | B6: 46.081662 | C6: 20 | D6: 0 | E6: 0 | F6: 0 | G6: 20 | H6: 30 | I6: 20 | J6: 30 | K6: 0 | L6: STOPPED | M6: =A6-A5 -> 0.049220085 | N6: =C6-B6 -> -26.081662 | O6: =ABS(N6)*M6 -> 1.2837416 | P6: =N6^2 * M6 -> 33.482116 | Q6: =IF(C6<>C5, "OSCILLATION", "--") -> --
A7: 1.7646154e+09 | B7: 47.696769 | C7: 20 | D7: 0 | E7: 0 | F7: 0 | G7: 20 | H7: 30 | I7: 20 | J7: 30 | K7: 0 | L7: STOPPED | M7: =A7-A6 -> 0.050799847 | N7: =C7-B7 -> -27.696769 | O7: =ABS(N7)*M7 -> 1.4069916 | P7: =N7^2 * M7 -> 38.969122 | Q7: =IF(C7<>C6, "OSCILLATION", "--") -> -- | R7: OSCILLATION | S7: A->B | T7: =A1236-A440 -> 39.94523 | U7: =T8/T7 -> 19.927286
A8: 1.7646154e+09 | B8: 45.03082 | C8: 20 | D8: 0 | E8: 0 | F8: 0 | G8: 20 | H8: 30 | I8: 20 | J8: 30 | K8: 0 | L8: STOPPED | M8: =A8-A7 -> 0.049520016 | N8: =C8-B8 -> -25.03082 | O8: =ABS(N8)*M8 -> 1.2395266 | P8: =N8^2 * M8 -> 31.026368 | Q8: =IF(C8<>C7, "OSCILLATION", "--") -> -- | R8: Rows: | S8: 440:837 | T8: =1236-440 -> 796
A9: 1.7646154e+09 | B9: 46.044862 | C9: 20 | D9: 0 | E9: 0 | F9: 0 | G9: 20 | H9: 30 | I9: 20 | J9: 30 | K9: 0 | L9: STOPPED | M9: =A9-A8 -> 0.051350117 | N9: =C9-B9 -> -26.044862 | O9: =ABS(N9)*M9 -> 1.3374067 | P9: =N9^2 * M9 -> 34.832574 | Q9: =IF(C9<>C8, "OSCILLATION", "--") -> -- | R9: SP_new | S9: =30 -> 30
A10: 1.7646154e+09 | B10: 45.885396 | C10: 20 | D10: 0 | E10: 0 | F10: 0 | G10: 20 | H10: 30 | I10: 20 | J10: 30 | K10: 0 | L10: STOPPED | M10: =A10-A9 -> 0.050839901 | N10: =C10-B10 -> -25.885396 | O10: =ABS(N10)*M10 -> 1.316011 | P10: =N10^2 * M10 -> 34.065465 | Q10: =IF(C10<>C9, "OSCILLATION", "--") -> -- | R10: PV_peak | S10: =_xlfn.MAXIFS(B440:B837, B440:B837, "<60") -> 35.180712
A11: 1.7646154e+09 | B11: 45.795441 | C11: 20 | D11: 0 | E11: 0 | F11: 0 | G11: 20 | H11: 30 | I11: 20 | J11: 30 | K11: 0 | L11: STOPPED | M11: =A11-A10 -> 0.048939943 | N11: =C11-B11 -> -25.795441 | O11: =ABS(N11)*M11 -> 1.2624274 | P11: =N11^2 * M11 -> 32.564871 | Q11: =IF(C11<>C10, "OSCILLATION", "--") -> -- | R11: Overshoot (%) | S11: =(ABS(S10-S9)/S9)*100 -> 17.269039 | T11: A lower percentage here means less overshoot/better stability.
A12: 1.7646154e+09 | B12: 45.648241 | C12: 20 | D12: 0 | E12: 0 | F12: 0 | G12: 20 | H12: 30 | I12: 20 | J12: 30 | K12: 0 | L12: STOPPED | M12: =A12-A11 -> 0.050710201 | N12: =C12-B12 -> -25.648241 | O12: =ABS(N12)*M12 -> 1.3006275 | P12: =N12^2 * M12 -> 33.358807 | Q12: =IF(C12<>C11, "OSCILLATION", "--") -> --
A13: 1.7646154e+09 | B13: 45.280242 | C13: 20 | D13: 0 | E13: 0 | F13: 0 | G13: 20 | H13: 30 | I13: 20 | J13: 30 | K13: 0 | L13: STOPPED | M13: =A13-A12 -> 0.049679995 | N13: =C13-B13 -> -25.280242 | O13: =ABS(N13)*M13 -> 1.2559223 | P13: =N13^2 * M13 -> 31.750019 | Q13: =IF(C13<>C12, "OSCILLATION", "--") -> -- | R13: Fall Time: | S13: =S18-S17 -> 1.2548101 | T13: A lower time here means faster response to the "fan off" command.
A14: 1.7646154e+09 | B14: 42.279005 | C14: 20 | D14: 0 | E14: 0 | F14: 0 | G14: 20 | H14: 30 | I14: 20 | J14: 30 | K14: 0 | L14: STOPPED | M14: =A14-A13 -> 0.051839828 | N14: =C14-B14 -> -22.279005 | O14: =ABS(N14)*M14 -> 1.1549398 | P14: =N14^2 * M14 -> 25.73091 | Q14: =IF(C14<>C13, "OSCILLATION", "--") -> -- | R14: Total Change (cm) | S14: =30-20 -> 10
A15: 1.7646154e+09 | B15: 45.546019 | C15: 20 | D15: 0 | E15: 0 | F15: 0 | G15: 20 | H15: 30 | I15: 20 | J15: 30 | K15: 0 | L15: STOPPED | M15: =A15-A14 -> 0.048900127 | N15: =C15-B15 -> -25.546019 | O15: =ABS(N15)*M15 -> 1.2492036 | P15: =N15^2 * M15 -> 31.912179 | Q15: =IF(C15<>C14, "OSCILLATION", "--") -> -- | R15: 10% Point (PV_10) (cm) | S15: =20+(10*0.1) -> 21
A16: 1.7646154e+09 | B16: 45.631886 | C16: 20 | D16: 0 | E16: 0 | F16: 0 | G16: 20 | H16: 30 | I16: 20 | J16: 30 | K16: 0 | L16: STOPPED | M16: =A16-A15 -> 0.050309896 | N16: =C16-B16 -> -25.631886 | O16: =ABS(N16)*M16 -> 1.2895375 | P16: =N16^2 * M16 -> 33.053278 | Q16: =IF(C16<>C15, "OSCILLATION", "--") -> -- | R16: 90% Point (PV_90) (cm) | S16: =20+(10*0.9) -> 29
A17: 1.7646154e+09 | B17: 45.554197 | C17: 20 | D17: 0 | E17: 0 | F17: 0 | G17: 20 | H17: 30 | I17: 20 | J17: 30 | K17: 0 | L17: STOPPED | M17: =A17-A16 -> 0.050510168 | N17: =C17-B17 -> -25.554197 | O17: =ABS(N17)*M17 -> 1.2907468 | P17: =N17^2 * M17 -> 32.983997 | Q17: =IF(C17<>C16, "OSCILLATION", "--") -> -- | R17: Time at 10% | S17: =A442 -> 1.7646154e+09 | T17: Row 442 | U17: (First row after setpoint change where distance ≥ 21)
A18: 1.7646154e+09 | B18: 46.371973 | C18: 20 | D18: 0 | E18: 0 | F18: 0 | G18: 20 | H18: 30 | I18: 20 | J18: 30 | K18: 0 | L18: STOPPED | M18: =A18-A17 -> 0.050159931 | N18: =C18-B18 -> -26.371973 | O18: =ABS(N18)*M18 -> 1.3228163 | P18: =N18^2 * M18 -> 34.885276 | Q18: =IF(C18<>C17, "OSCILLATION", "--") -> -- | R18: Time at 90% | S18: =A467 -> 1.7646154e+09 | T18: Row 467 | U18: (First row after setpoint change where distance ≥ 29)
A19: 1.7646154e+09 | B19: 45.120776 | C19: 20 | D19: 0 | E19: 0 | F19: 0 | G19: 20 | H19: 30 | I19: 20 | J19: 30 | K19: 0 | L19: STOPPED | M19: =A19-A18 -> 0.050029993 | N19: =C19-B19 -> -25.120776 | O19: =ABS(N19)*M19 -> 1.2567922 | P19: =N19^2 * M19 -> 31.571596 | Q19: =IF(C19<>C18, "OSCILLATION", "--") -> --
A20: 1.7646154e+09 | B20: 45.995796 | C20: 20 | D20: 0 | E20: 0 | F20: 0 | G20: 20 | H20: 30 | I20: 20 | J20: 30 | K20: 0 | L20: STOPPED | M20: =A20-A19 -> 0.05053997 | N20: =C20-B20 -> -25.995796 | O20: =ABS(N20)*M20 -> 1.3138267 | P20: =N20^2 * M20 -> 34.153972 | Q20: =IF(C20<>C19, "OSCILLATION", "--") -> -- | R20: OSCILLATION | S20: B->A
A21: 1.7646154e+09 | B21: 46.63775 | C21: 20 | D21: 0 | E21: 0 | F21: 0 | G21: 20 | H21: 30 | I21: 20 | J21: 30 | K21: 0 | L21: STOPPED | M21: =A21-A20 -> 0.049720049 | N21: =C21-B21 -> -26.63775 | O21: =ABS(N21)*M21 -> 1.3244302 | P21: =N21^2 * M21 -> 35.279841 | Q21: =IF(C21<>C20, "OSCILLATION", "--") -> -- | R21: Rows: | S21: 838:1236
A22: 1.7646154e+09 | B22: 46.093929 | C22: 20 | D22: 0 | E22: 0 | F22: 0 | G22: 20 | H22: 30 | I22: 20 | J22: 30 | K22: 0 | L22: STOPPED | M22: =A22-A21 -> 0.05005002 | N22: =C22-B22 -> -26.093929 | O22: =ABS(N22)*M22 -> 1.3060017 | P22: =N22^2 * M22 -> 34.078714 | Q22: =IF(C22<>C21, "OSCILLATION", "--") -> -- | R22: SP_new | S22: =20 -> 20
A23: 1.7646154e+09 | B23: 45.623708 | C23: 20 | D23: 0 | E23: 0 | F23: 0 | G23: 20 | H23: 30 | I23: 20 | J23: 30 | K23: 0 | L23: STOPPED | M23: =A23-A22 -> 0.050669909 | N23: =C23-B23 -> -25.623708 | O23: =ABS(N23)*M23 -> 1.2983509 | P23: =N23^2 * M23 -> 33.268565 | Q23: =IF(C23<>C22, "OSCILLATION", "--") -> -- | R23: PV_valley | S23: =MIN(B838:B1236) -> 17.03018
A24: 1.7646154e+09 | B24: 45.128953 | C24: 20 | D24: 0 | E24: 0 | F24: 0 | G24: 20 | H24: 30 | I24: 20 | J24: 30 | K24: 0 | L24: STOPPED | M24: =A24-A23 -> 0.050689936 | N24: =C24-B24 -> -25.128953 | O24: =ABS(N24)*M24 -> 1.273785 | P24: =N24^2 * M24 -> 32.008885 | Q24: =IF(C24<>C23, "OSCILLATION", "--") -> -- | R24: Overshoot (%) | S24: =(ABS(S23-S22)/S22)*100 -> 14.849102 | T24: A lower percentage here means less undershoot/better stability.
A25: 1.7646154e+09 | B25: 45.227087 | C25: 20 | D25: 0 | E25: 0 | F25: 0 | G25: 20 | H25: 30 | I25: 20 | J25: 30 | K25: 0 | L25: STOPPED | M25: =A25-A24 -> 0.050430059 | N25: =C25-B25 -> -25.227087 | O25: =ABS(N25)*M25 -> 1.2722035 | P25: =N25^2 * M25 -> 32.093987 | Q25: =IF(C25<>C24, "OSCILLATION", "--") -> --
A26: 1.7646154e+09 | B26: 45.61553 | C26: 20 | D26: 0 | E26: 0 | F26: 0 | G26: 20 | H26: 30 | I26: 20 | J26: 30 | K26: 0 | L26: STOPPED | M26: =A26-A25 -> 0.051229954 | N26: =C26-B26 -> -25.61553 | O26: =ABS(N26)*M26 -> 1.3122824 | P26: =N26^2 * M26 -> 33.61481 | Q26: =IF(C26<>C25, "OSCILLATION", "--") -> -- | R26: Rise Time: | S26: =S31-S30 -> 6.3232801 | T26: A lower time here means faster response to the "fan on" command.
A27: 1.7646154e+09 | B27: 44.863176 | C27: 20 | D27: 0 | E27: 0 | F27: 0 | G27: 20 | H27: 30 | I27: 20 | J27: 30 | K27: 0 | L27: STOPPED | M27: =A27-A26 -> 0.048680067 | N27: =C27-B27 -> -24.863176 | O27: =ABS(N27)*M27 -> 1.2103411 | P27: =N27^2 * M27 -> 30.092924 | Q27: =IF(C27<>C26, "OSCILLATION", "--") -> -- | R27: Total Change (cm) | S27: =30-20 -> 10
A28: 1.7646154e+09 | B28: 45.668685 | C28: 20 | D28: 0 | E28: 0 | F28: 0 | G28: 20 | H28: 30 | I28: 20 | J28: 30 | K28: 0 | L28: STOPPED | M28: =A28-A27 -> 0.049269915 | N28: =C28-B28 -> -25.668685 | O28: =ABS(N28)*M28 -> 1.2646939 | P28: =N28^2 * M28 -> 32.463031 | Q28: =IF(C28<>C27, "OSCILLATION", "--") -> -- | R28: 10% Point (PV_10) (cm) | S28: =30-(10*0.1) -> 29
A29: 1.7646154e+09 | B29: 45.971262 | C29: 20 | D29: 0 | E29: 0 | F29: 0 | G29: 20 | H29: 30 | I29: 20 | J29: 30 | K29: 0 | L29: STOPPED | M29: =A29-A28 -> 0.050250053 | N29: =C29-B29 -> -25.971262 | O29: =ABS(N29)*M29 -> 1.3050573 | P29: =N29^2 * M29 -> 33.893986 | Q29: =IF(C29<>C28, "OSCILLATION", "--") -> -- | R29: 90% Point (PV_90) (cm) | S29: =30-(10*0.9) -> 21
A30: 1.7646154e+09 | B30: 45.897663 | C30: 20 | D30: 0 | E30: 0 | F30: 0 | G30: 20 | H30: 30 | I30: 20 | J30: 30 | K30: 0 | L30: STOPPED | M30: =A30-A29 -> 0.051490068 | N30: =C30-B30 -> -25.897663 | O30: =ABS(N30)*M30 -> 1.3334724 | P30: =N30^2 * M30 -> 34.533819 | Q30: =IF(C30<>C29, "OSCILLATION", "--") -> -- | R30: Time at 10% | S30: =A848 -> 1.7646154e+09 | T30: Row 848 | U30: (First row after setpoint change where distance ≤ 29)
A31: 1.7646154e+09 | B31: 45.685041 | C31: 20 | D31: 0 | E31: 0 | F31: 0 | G31: 20 | H31: 30 | I31: 20 | J31: 30 | K31: 0 | L31: STOPPED | M31: =A31-A30 -> 0.048840046 | N31: =C31-B31 -> -25.685041 | O31: =ABS(N31)*M31 -> 1.2544586 | P31: =N31^2 * M31 -> 32.22082 | Q31: =IF(C31<>C30, "OSCILLATION", "--") -> -- | R31: Time at 90% | S31: =A974 -> 1.7646154e+09 | T31: Row 974 | U31: (First row after setpoint change where distance ≤ 21)
A32: 1.7646154e+09 | B32: 45.586908 | C32: 20 | D32: 0 | E32: 0 | F32: 0 | G32: 20 | H32: 30 | I32: 20 | J32: 30 | K32: 0 | L32: STOPPED | M32: =A32-A31 -> 0.050289869 | N32: =C32-B32 -> -25.586908 | O32: =ABS(N32)*M32 -> 1.2867623 | P32: =N32^2 * M32 -> 32.924267 | Q32: =IF(C32<>C31, "OSCILLATION", "--") -> --
A33: 1.7646154e+09 | B33: 45.926285 | C33: 20 | D33: 0 | E33: 0 | F33: 0 | G33: 20 | H33: 30 | I33: 20 | J33: 30 | K33: 0 | L33: STOPPED | M33: =A33-A32 -> 0.050780058 | N33: =C33-B33 -> -25.926285 | O33: =ABS(N33)*M33 -> 1.3165382 | P33: =N33^2 * M33 -> 34.132945 | Q33: =IF(C33<>C32, "OSCILLATION", "--") -> --
A34: 1.7646154e+09 | B34: 45.50513 | C34: 20 | D34: 0 | E34: 0 | F34: 0 | G34: 20 | H34: 30 | I34: 20 | J34: 30 | K34: 0 | L34: STOPPED | M34: =A34-A33 -> 0.04975009 | N34: =C34-B34 -> -25.50513 | O34: =ABS(N34)*M34 -> 1.2688825 | P34: =N34^2 * M34 -> 32.363014 | Q34: =IF(C34<>C33, "OSCILLATION", "--") -> --
A35: 1.7646154e+09 | B35: 45.660508 | C35: 20 | D35: 0 | E35: 0 | F35: 0 | G35: 20 | H35: 30 | I35: 20 | J35: 30 | K35: 0 | L35: STOPPED | M35: =A35-A34 -> 0.050949812 | N35: =C35-B35 -> -25.660508 | O35: =ABS(N35)*M35 -> 1.307398 | P35: =N35^2 * M35 -> 33.548497 | Q35: =IF(C35<>C34, "OSCILLATION", "--") -> --
A36: 1.7646154e+09 | B36: 46.63775 | C36: 20 | D36: 0 | E36: 0 | F36: 0 | G36: 20 | H36: 30 | I36: 20 | J36: 30 | K36: 0 | L36: STOPPED | M36: =A36-A35 -> 0.051150084 | N36: =C36-B36 -> -26.63775 | O36: =ABS(N36)*M36 -> 1.3625231 | P36: =N36^2 * M36 -> 36.29455 | Q36: =IF(C36<>C35, "OSCILLATION", "--") -> --
A37: 1.7646154e+09 | B37: 46.376061 | C37: 20 | D37: 0 | E37: 0 | F37: 0 | G37: 20 | H37: 30 | I37: 20 | J37: 30 | K37: 0 | L37: STOPPED | M37: =A37-A36 -> 0.049220085 | N37: =C37-B37 -> -26.376061 | O37: =ABS(N37)*M37 -> 1.298232 | P37: =N37^2 * M37 -> 34.242247 | Q37: =IF(C37<>C36, "OSCILLATION", "--") -> --
A38: 1.7646154e+09 | B38: 45.235264 | C38: 20 | D38: 0 | E38: 0 | F38: 0 | G38: 20 | H38: 30 | I38: 20 | J38: 30 | K38: 0 | L38: STOPPED | M38: =A38-A37 -> 0.050079823 | N38: =C38-B38 -> -25.235264 | O38: =ABS(N38)*M38 -> 1.2637776 | P38: =N38^2 * M38 -> 31.891761 | Q38: =IF(C38<>C37, "OSCILLATION", "--") -> --
A39: 1.7646154e+09 | B39: 46.41695 | C39: 20 | D39: 0 | E39: 0 | F39: 0 | G39: 20 | H39: 30 | I39: 20 | J39: 30 | K39: 0 | L39: STOPPED | M39: =A39-A38 -> 0.051789999 | N39: =C39-B39 -> -26.41695 | O39: =ABS(N39)*M39 -> 1.3681338 | P39: =N39^2 * M39 -> 36.141923 | Q39: =IF(C39<>C38, "OSCILLATION", "--") -> --
A40: 1.7646154e+09 | B40: 45.603263 | C40: 20 | D40: 0 | E40: 0 | F40: 0 | G40: 20 | H40: 30 | I40: 20 | J40: 30 | K40: 0 | L40: STOPPED | M40: =A40-A39 -> 0.048720121 | N40: =C40-B40 -> -25.603263 | O40: =ABS(N40)*M40 -> 1.2473941 | P40: =N40^2 * M40 -> 31.93736 | Q40: =IF(C40<>C39, "OSCILLATION", "--") -> --
...

Sheet sensor_log_cpu
A1: timestamp | B1: distance | C1: setpoint | D1: duty | E1: delay_ms | F1: loss_rate | G1: osc_a | H1: osc_b | I1: osc_period | J1: next_setpoint | K1: switch_in | L1: pid_status | M1: Time Step (dt) | N1: Error (E) | O1: |E| * dt | P1: E^2 * dt
A2: 1.764616e+09 | B2: 47.443259 | C2: 20 | D2: 0 | E2: 0 | F2: 0 | G2: 20 | H2: 30 | I2: 20 | J2: 30 | K2: 0 | L2: STOPPED | M2: (Time Between Samples) | N2: (Instantaneous Tracking Error) | O2: (Instantaneous Area under the Absolute Error Curve) | P2: (Instantaneous Area under the Squared Error Curve) | R2: SUM dt | S2: =SUM(M748:M1544) -> 39.99761
A3: 1.764616e+09 | B3: 47.463703 | C3: 20 | D3: 0 | E3: 0 | F3: 0 | G3: 20 | H3: 30 | I3: 20 | J3: 30 | K3: 0 | L3: STOPPED | M3: =A3-A2 -> 0.050159931 | N3: =C3-B3 -> -27.463703 | O3: =ABS(N3)*M3 -> 1.3775775 | P3: =N3^2 * M3 -> 37.833378 | Q3: =IF(C3<>C2, "OSCILLATION", "--") -> -- | R3: SUM E | S3: =SUM(N748:N1544) -> -1491.8089
A4: 1.764616e+09 | B4: 47.484148 | C4: 20 | D4: 0 | E4: 0 | F4: 0 | G4: 20 | H4: 30 | I4: 20 | J4: 30 | K4: 0 | L4: STOPPED | M4: =A4-A3 -> 0.049589872 | N4: =C4-B4 -> -27.484148 | O4: =ABS(N4)*M4 -> 1.3629354 | P4: =N4^2 * M4 -> 37.459117 | Q4: =IF(C4<>C3, "OSCILLATION", "--") -> -- | R4: ="SUM "&O1 -> SUM |E| * dt | S4: =SUM(O748:O1544) -> 110.52882 | T4: Total Integral Absolute Error (IAE)
A5: 1.764616e+09 | B5: 47.050726 | C5: 20 | D5: 0 | E5: 0 | F5: 0 | G5: 20 | H5: 30 | I5: 20 | J5: 30 | K5: 0 | L5: STOPPED | M5: =A5-A4 -> 0.050510168 | N5: =C5-B5 -> -27.050726 | O5: =ABS(N5)*M5 -> 1.3663367 | P5: =N5^2 * M5 -> 36.960401 | Q5: =IF(C5<>C4, "OSCILLATION", "--") -> -- | R5: ="SUM "&P1 -> SUM E^2 * dt | S5: =SUM(P748:P1544) -> 749.88803 | T5: Total Integral Squared Error (ISE)
A6: 1.764616e+09 | B6: 47.058904 | C6: 20 | D6: 0 | E6: 0 | F6: 0 | G6: 20 | H6: 30 | I6: 20 | J6: 30 | K6: 0 | L6: STOPPED | M6: =A6-A5 -> 0.050189972 | N6: =C6-B6 -> -27.058904 | O6: =ABS(N6)*M6 -> 1.3580856 | P6: =N6^2 * M6 -> 36.748309 | Q6: =IF(C6<>C5, "OSCILLATION", "--") -> --
A7: 1.764616e+09 | B7: 46.703172 | C7: 20 | D7: 0 | E7: 0 | F7: 0 | G7: 20 | H7: 30 | I7: 20 | J7: 30 | K7: 0 | L7: STOPPED | M7: =A7-A6 -> 0.051039934 | N7: =C7-B7 -> -26.703172 | O7: =ABS(N7)*M7 -> 1.3629281 | P7: =N7^2 * M7 -> 36.394504 | Q7: =IF(C7<>C6, "OSCILLATION", "--") -> --
A8: 1.764616e+09 | B8: 47.083437 | C8: 20 | D8: 0 | E8: 0 | F8: 0 | G8: 20 | H8: 30 | I8: 20 | J8: 30 | K8: 0 | L8: STOPPED | M8: =A8-A7 -> 0.050980091 | N8: =C8-B8 -> -27.083437 | O8: =ABS(N8)*M8 -> 1.3807161 | P8: =N8^2 * M8 -> 37.394538 | Q8: =IF(C8<>C7, "OSCILLATION", "--") -> -- | R8: OSCILLATION | S8: A->B
A9: 1.764616e+09 | B9: 47.083437 | C9: 20 | D9: 0 | E9: 0 | F9: 0 | G9: 20 | H9: 30 | I9: 20 | J9: 30 | K9: 0 | L9: STOPPED | M9: =A9-A8 -> 0.048559904 | N9: =C9-B9 -> -27.083437 | O9: =ABS(N9)*M9 -> 1.3151691 | P9: =N9^2 * M9 -> 35.619301 | Q9: =IF(C9<>C8, "OSCILLATION", "--") -> -- | R9: Rows: | S9: 748:1146
A10: 1.764616e+09 | B10: 47.435081 | C10: 20 | D10: 0 | E10: 0 | F10: 0 | G10: 20 | H10: 30 | I10: 20 | J10: 30 | K10: 0 | L10: STOPPED | M10: =A10-A9 -> 0.049819946 | N10: =C10-B10 -> -27.435081 | O10: =ABS(N10)*M10 -> 1.3668143 | P10: =N10^2 * M10 -> 37.49866 | Q10: =IF(C10<>C9, "OSCILLATION", "--") -> -- | R10: SP_new | S10: =30 -> 30
A11: 1.764616e+09 | B11: 47.046638 | C11: 20 | D11: 0 | E11: 0 | F11: 0 | G11: 20 | H11: 30 | I11: 20 | J11: 30 | K11: 0 | L11: STOPPED | M11: =A11-A10 -> 0.050209999 | N11: =C11-B11 -> -27.046638 | O11: =ABS(N11)*M11 -> 1.3580116 | P11: =N11^2 * M11 -> 36.729649 | Q11: =IF(C11<>C10, "OSCILLATION", "--") -> -- | R11: PV_peak | S11: =_xlfn.MAXIFS(B748:B1146, B748:B1146, "<60") -> 32.404363
A12: 1.764616e+09 | B12: 47.062993 | C12: 20 | D12: 0 | E12: 0 | F12: 0 | G12: 20 | H12: 30 | I12: 20 | J12: 30 | K12: 0 | L12: STOPPED | M12: =A12-A11 -> 0.050630093 | N12: =C12-B12 -> -27.062993 | O12: =ABS(N12)*M12 -> 1.3702018 | P12: =N12^2 * M12 -> 37.081763 | Q12: =IF(C12<>C11, "OSCILLATION", "--") -> -- | R12: Overshoot (%) | S12: =(ABS(S11-S10)/S10)*100 -> 8.0145439
A13: 1.764616e+09 | B13: 47.050726 | C13: 20 | D13: 0 | E13: 0 | F13: 0 | G13: 20 | H13: 30 | I13: 20 | J13: 30 | K13: 0 | L13: STOPPED | M13: =A13-A12 -> 0.052779913 | N13: =C13-B13 -> -27.050726 | O13: =ABS(N13)*M13 -> 1.427735 | P13: =N13^2 * M13 -> 38.621268 | Q13: =IF(C13<>C12, "OSCILLATION", "--") -> --
A14: 1.764616e+09 | B14: 47.087526 | C14: 20 | D14: 0 | E14: 0 | F14: 0 | G14: 20 | H14: 30 | I14: 20 | J14: 30 | K14: 0 | L14: STOPPED | M14: =A14-A13 -> 0.048629999 | N14: =C14-B14 -> -27.087526 | O14: =ABS(N14)*M14 -> 1.3172664 | P14: =N14^2 * M14 -> 35.681488 | Q14: =IF(C14<>C13, "OSCILLATION", "--") -> --
A15: 1.764616e+09 | B15: 47.471881 | C15: 20 | D15: 0 | E15: 0 | F15: 0 | G15: 20 | H15: 30 | I15: 20 | J15: 30 | K15: 0 | L15: STOPPED | M15: =A15-A14 -> 0.050090075 | N15: =C15-B15 -> -27.471881 | O15: =ABS(N15)*M15 -> 1.3760686 | P15: =N15^2 * M15 -> 37.803192 | Q15: =IF(C15<>C14, "OSCILLATION", "--") -> -- | R15: Fall Time: | S15: =S20-S19 -> 2.3075202
A16: 1.764616e+09 | B16: 47.459614 | C16: 20 | D16: 0 | E16: 0 | F16: 0 | G16: 20 | H16: 30 | I16: 20 | J16: 30 | K16: 0 | L16: STOPPED | M16: =A16-A15 -> 0.049769878 | N16: =C16-B16 -> -27.459614 | O16: =ABS(N16)*M16 -> 1.3666617 | P16: =N16^2 * M16 -> 37.528002 | Q16: =IF(C16<>C15, "OSCILLATION", "--") -> -- | R16: Total Change (cm) | S16: =30-20 -> 10
A17: 1.764616e+09 | B17: 48.976588 | C17: 20 | D17: 0 | E17: 0 | F17: 0 | G17: 20 | H17: 30 | I17: 20 | J17: 30 | K17: 0 | L17: STOPPED | M17: =A17-A16 -> 0.05136013 | N17: =C17-B17 -> -28.976588 | O17: =ABS(N17)*M17 -> 1.4882413 | P17: =N17^2 * M17 -> 43.124157 | Q17: =IF(C17<>C16, "OSCILLATION", "--") -> -- | R17: 10% Point (PV_10) (cm) | S17: =20+(10*0.1) -> 21
A18: 1.764616e+09 | B18: 47.11206 | C18: 20 | D18: 0 | E18: 0 | F18: 0 | G18: 20 | H18: 30 | I18: 20 | J18: 30 | K18: 0 | L18: STOPPED | M18: =A18-A17 -> 0.049599886 | N18: =C18-B18 -> -27.11206 | O18: =ABS(N18)*M18 -> 1.3447551 | P18: =N18^2 * M18 -> 36.459079 | Q18: =IF(C18<>C17, "OSCILLATION", "--") -> -- | R18: 90% Point (PV_90) (cm) | S18: =20+(10*0.9) -> 29
A19: 1.764616e+09 | B19: 47.091615 | C19: 20 | D19: 0 | E19: 0 | F19: 0 | G19: 20 | H19: 30 | I19: 20 | J19: 30 | K19: 0 | L19: STOPPED | M19: =A19-A18 -> 0.049300194 | N19: =C19-B19 -> -27.091615 | O19: =ABS(N19)*M19 -> 1.3356219 | P19: =N19^2 * M19 -> 36.184154 | Q19: =IF(C19<>C18, "OSCILLATION", "--") -> -- | R19: Time at 10% | S19: =A749 -> 1.764616e+09 | T19: Row 749 | U19: (First row after setpoint change where distance ≥ 21)
A20: 1.764616e+09 | B20: 47.43917 | C20: 20 | D20: 0 | E20: 0 | F20: 0 | G20: 20 | H20: 30 | I20: 20 | J20: 30 | K20: 0 | L20: STOPPED | M20: =A20-A19 -> 0.050040007 | N20: =C20-B20 -> -27.43917 | O20: =ABS(N20)*M20 -> 1.3730562 | P20: =N20^2 * M20 -> 37.675524 | Q20: =IF(C20<>C19, "OSCILLATION", "--") -> -- | R20: Time at 90% | S20: =A795 -> 1.764616e+09 | T20: Row 795 | U20: (First row after setpoint change where distance ≥ 29)
A21: 1.764616e+09 | B21: 47.062993 | C21: 20 | D21: 0 | E21: 0 | F21: 0 | G21: 20 | H21: 30 | I21: 20 | J21: 30 | K21: 0 | L21: STOPPED | M21: =A21-A20 -> 0.050529957 | N21: =C21-B21 -> -27.062993 | O21: =ABS(N21)*M21 -> 1.3674919 | P21: =N21^2 * M21 -> 37.008423 | Q21: =IF(C21<>C20, "OSCILLATION", "--") -> --
A22: 1.764616e+09 | B22: 47.067082 | C22: 20 | D22: 0 | E22: 0 | F22: 0 | G22: 20 | H22: 30 | I22: 20 | J22: 30 | K22: 0 | L22: STOPPED | M22: =A22-A21 -> 0.049959898 | N22: =C22-B22 -> -27.067082 | O22: =ABS(N22)*M22 -> 1.3522687 | P22: =N22^2 * M22 -> 36.601966 | Q22: =IF(C22<>C21, "OSCILLATION", "--") -> --
A23: 1.764616e+09 | B23: 47.091615 | C23: 20 | D23: 0 | E23: 0 | F23: 0 | G23: 20 | H23: 30 | I23: 20 | J23: 30 | K23: 0 | L23: STOPPED | M23: =A23-A22 -> 0.050270081 | N23: =C23-B23 -> -27.091615 | O23: =ABS(N23)*M23 -> 1.3618977 | P23: =N23^2 * M23 -> 36.896008 | Q23: =IF(C23<>C22, "OSCILLATION", "--") -> -- | R23: OSCILLATION | S23: B->A
A24: 1.764616e+09 | B24: 47.467792 | C24: 20 | D24: 0 | E24: 0 | F24: 0 | G24: 20 | H24: 30 | I24: 20 | J24: 30 | K24: 0 | L24: STOPPED | M24: =A24-A23 -> 0.049659967 | N24: =C24-B24 -> -27.467792 | O24: =ABS(N24)*M24 -> 1.3640497 | P24: =N24^2 * M24 -> 37.467432 | Q24: =IF(C24<>C23, "OSCILLATION", "--") -> -- | R24: Rows: | S24: 1147:1544
A25: 1.764616e+09 | B25: 47.467792 | C25: 20 | D25: 0 | E25: 0 | F25: 0 | G25: 20 | H25: 30 | I25: 20 | J25: 30 | K25: 0 | L25: STOPPED | M25: =A25-A24 -> 0.050659895 | N25: =C25-B25 -> -27.467792 | O25: =ABS(N25)*M25 -> 1.3915155 | P25: =N25^2 * M25 -> 38.221857 | Q25: =IF(C25<>C24, "OSCILLATION", "--") -> -- | R25: SP_new | S25: =20 -> 20
A26: 1.764616e+09 | B26: 47.034371 | C26: 20 | D26: 0 | E26: 0 | F26: 0 | G26: 20 | H26: 30 | I26: 20 | J26: 30 | K26: 0 | L26: STOPPED | M26: =A26-A25 -> 0.050170183 | N26: =C26-B26 -> -27.034371 | O26: =ABS(N26)*M26 -> 1.3563193 | P26: =N26^2 * M26 -> 36.66724 | Q26: =IF(C26<>C25, "OSCILLATION", "--") -> -- | R26: PV_valley | S26: =MIN(B1147:B1544) -> 19.622529
A27: 1.764616e+09 | B27: 47.447348 | C27: 20 | D27: 0 | E27: 0 | F27: 0 | G27: 20 | H27: 30 | I27: 20 | J27: 30 | K27: 0 | L27: STOPPED | M27: =A27-A26 -> 0.051869869 | N27: =C27-B27 -> -27.447348 | O27: =ABS(N27)*M27 -> 1.4236903 | P27: =N27^2 * M27 -> 39.076524 | Q27: =IF(C27<>C26, "OSCILLATION", "--") -> -- | R27: Overshoot (%) | S27: =(ABS(S26-S25)/S25)*100 -> 1.8873572
A28: 1.764616e+09 | B28: 47.054815 | C28: 20 | D28: 0 | E28: 0 | F28: 0 | G28: 20 | H28: 30 | I28: 20 | J28: 30 | K28: 0 | L28: STOPPED | M28: =A28-A27 -> 0.048690081 | N28: =C28-B28 -> -27.054815 | O28: =ABS(N28)*M28 -> 1.3173011 | P28: =N28^2 * M28 -> 35.639339 | Q28: =IF(C28<>C27, "OSCILLATION", "--") -> --
A29: 1.764616e+09 | B29: 47.062993 | C29: 20 | D29: 0 | E29: 0 | F29: 0 | G29: 20 | H29: 30 | I29: 20 | J29: 30 | K29: 0 | L29: STOPPED | M29: =A29-A28 -> 0.050149918 | N29: =C29-B29 -> -27.062993 | O29: =ABS(N29)*M29 -> 1.3572069 | P29: =N29^2 * M29 -> 36.73008 | Q29: =IF(C29<>C28, "OSCILLATION", "--") -> --
A30: 1.764616e+09 | B30: 47.455525 | C30: 20 | D30: 0 | E30: 0 | F30: 0 | G30: 20 | H30: 30 | I30: 20 | J30: 30 | K30: 0 | L30: STOPPED | M30: =A30-A29 -> 0.049950123 | N30: =C30-B30 -> -27.455525 | O30: =ABS(N30)*M30 -> 1.3714069 | P30: =N30^2 * M30 -> 37.652696 | Q30: =IF(C30<>C29, "OSCILLATION", "--") -> -- | R30: Rise Time: | S30: =S35-S34 -> 7.8306899
A31: 1.764616e+09 | B31: 47.07526 | C31: 20 | D31: 0 | E31: 0 | F31: 0 | G31: 20 | H31: 30 | I31: 20 | J31: 30 | K31: 0 | L31: STOPPED | M31: =A31-A30 -> 0.05005002 | N31: =C31-B31 -> -27.07526 | O31: =ABS(N31)*M31 -> 1.3551173 | P31: =N31^2 * M31 -> 36.690153 | Q31: =IF(C31<>C30, "OSCILLATION", "--") -> -- | R31: Total Change (cm) | S31: =30-20 -> 10
A32: 1.764616e+09 | B32: 47.018015 | C32: 20 | D32: 0 | E32: 0 | F32: 0 | G32: 20 | H32: 30 | I32: 20 | J32: 30 | K32: 0 | L32: STOPPED | M32: =A32-A31 -> 0.051549911 | N32: =C32-B32 -> -27.018015 | O32: =ABS(N32)*M32 -> 1.3927763 | P32: =N32^2 * M32 -> 37.630052 | Q32: =IF(C32<>C31, "OSCILLATION", "--") -> -- | R32: 10% Point (PV_10) (cm) | S32: =30-(10*0.1) -> 29
A33: 1.764616e+09 | B33: 47.079349 | C33: 20 | D33: 0 | E33: 0 | F33: 0 | G33: 20 | H33: 30 | I33: 20 | J33: 30 | K33: 0 | L33: STOPPED | M33: =A33-A32 -> 0.049160004 | N33: =C33-B33 -> -27.079349 | O33: =ABS(N33)*M33 -> 1.3312209 | P33: =N33^2 * M33 -> 36.048594 | Q33: =IF(C33<>C32, "OSCILLATION", "--") -> -- | R33: 90% Point (PV_90) (cm) | S33: =30-(10*0.9) -> 21
A34: 1.764616e+09 | B34: 47.046638 | C34: 20 | D34: 0 | E34: 0 | F34: 0 | G34: 20 | H34: 30 | I34: 20 | J34: 30 | K34: 0 | L34: STOPPED | M34: =A34-A33 -> 0.050400019 | N34: =C34-B34 -> -27.046638 | O34: =ABS(N34)*M34 -> 1.363151 | P34: =N34^2 * M34 -> 36.868652 | Q34: =IF(C34<>C33, "OSCILLATION", "--") -> -- | R34: Time at 10% | S34: =A1169 -> 1.764616e+09 | T34: Row 1169 | U34: (First row after setpoint change where distance ≤ 29)
A35: 1.764616e+09 | B35: 47.467792 | C35: 20 | D35: 0 | E35: 0 | F35: 0 | G35: 20 | H35: 30 | I35: 20 | J35: 30 | K35: 0 | L35: STOPPED | M35: =A35-A34 -> 0.050260067 | N35: =C35-B35 -> -27.467792 | O35: =ABS(N35)*M35 -> 1.3805331 | P35: =N35^2 * M35 -> 37.920195 | Q35: =IF(C35<>C34, "OSCILLATION", "--") -> -- | R35: Time at 90% | S35: =A1325 -> 1.764616e+09 | T35: Row 1325 | U35: (First row after setpoint change where distance ≤ 21)
A36: 1.764616e+09 | B36: 47.067082 | C36: 20 | D36: 0 | E36: 0 | F36: 0 | G36: 20 | H36: 30 | I36: 20 | J36: 30 | K36: 0 | L36: STOPPED | M36: =A36-A35 -> 0.049569845 | N36: =C36-B36 -> -27.067082 | O36: =ABS(N36)*M36 -> 1.3417111 | P36: =N36^2 * M36 -> 36.316203 | Q36: =IF(C36<>C35, "OSCILLATION", "--") -> --
A37: 1.764616e+09 | B37: 47.480059 | C37: 20 | D37: 0 | E37: 0 | F37: 0 | G37: 20 | H37: 30 | I37: 20 | J37: 30 | K37: 0 | L37: STOPPED | M37: =A37-A36 -> 0.051040173 | N37: =C37-B37 -> -27.480059 | O37: =ABS(N37)*M37 -> 1.4025869 | P37: =N37^2 * M37 -> 38.543171 | Q37: =IF(C37<>C36, "OSCILLATION", "--") -> --
A38: 1.764616e+09 | B38: 47.058904 | C38: 20 | D38: 0 | E38: 0 | F38: 0 | G38: 20 | H38: 30 | I38: 20 | J38: 30 | K38: 0 | L38: STOPPED | M38: =A38-A37 -> 0.049929857 | N38: =C38-B38 -> -27.058904 | O38: =ABS(N38)*M38 -> 1.3510472 | P38: =N38^2 * M38 -> 36.557857 | Q38: =IF(C38<>C37, "OSCILLATION", "--") -> --
A39: 1.764616e+09 | B39: 47.067082 | C39: 20 | D39: 0 | E39: 0 | F39: 0 | G39: 20 | H39: 30 | I39: 20 | J39: 30 | K39: 0 | L39: STOPPED | M39: =A39-A38 -> 0.049790144 | N39: =C39-B39 -> -27.067082 | O39: =ABS(N39)*M39 -> 1.3476739 | P39: =N39^2 * M39 -> 36.4776 | Q39: =IF(C39<>C38, "OSCILLATION", "--") -> --
A40: 1.764616e+09 | B40: 47.418725 | C40: 20 | D40: 0 | E40: 0 | F40: 0 | G40: 20 | H40: 30 | I40: 20 | J40: 30 | K40: 0 | L40: STOPPED | M40: =A40-A39 -> 0.050559998 | N40: =C40-B40 -> -27.418725 | O40: =ABS(N40)*M40 -> 1.3862907 | P40: =N40^2 * M40 -> 38.010324 | Q40: =IF(C40<>C39, "OSCILLATION", "--") -> --
...

Sheet sensor_log_iperf
A1: timestamp | B1: distance | C1: setpoint | D1: duty | E1: delay_ms | F1: loss_rate | G1: osc_a | H1: osc_b | I1: osc_period | J1: next_setpoint | K1: switch_in | L1: pid_status | M1: Time Step (dt) | N1: Error (E) | O1: |E| * dt | P1: E^2 * dt
A2: 1.7646157e+09 | B2: 46.658194 | C2: 20 | D2: 0 | E2: 0 | F2: 0 | G2: 20 | H2: 30 | I2: 20 | J2: 30 | K2: 0 | L2: STOPPED | M2: (Time Between Samples) | N2: (Instantaneous Tracking Error) | O2: (Instantaneous Area under the Absolute Error Curve) | P2: (Instantaneous Area under the Squared Error Curve)
A3: 1.7646157e+09 | B3: 46.678638 | C3: 20 | D3: 0 | E3: 0 | F3: 0 | G3: 20 | H3: 30 | I3: 20 | J3: 30 | K3: 0 | L3: STOPPED | M3: =A3-A2 -> 0.048449993 | N3: =C3-B3 -> -26.678638 | O3: =ABS(N3)*M3 -> 1.2925799 | P3: =N3^2 * M3 -> 34.48427 | Q3: =IF(C3<>C2, "OSCILLATION", "--") -> -- | R3: SUM dt | S3: =SUM(M680:M1476) -> 39.99262
A4: 1.7646157e+09 | B4: 47.206104 | C4: 20 | D4: 0 | E4: 0 | F4: 0 | G4: 20 | H4: 30 | I4: 20 | J4: 30 | K4: 0 | L4: STOPPED | M4: =A4-A3 -> 0.05016017 | N4: =C4-B4 -> -27.206104 | O4: =ABS(N4)*M4 -> 1.3646628 | P4: =N4^2 * M4 -> 37.127157 | Q4: =IF(C4<>C3, "OSCILLATION", "--") -> -- | R4: SUM E | S4: =SUM(N680:N1476) -> -2988.4305
A5: 1.7646157e+09 | B5: 48.878455 | C5: 20 | D5: 0 | E5: 0 | F5: 0 | G5: 20 | H5: 30 | I5: 20 | J5: 30 | K5: 0 | L5: STOPPED | M5: =A5-A4 -> 0.05080986 | N5: =C5-B5 -> -28.878455 | O5: =ABS(N5)*M5 -> 1.4673103 | P5: =N5^2 * M5 -> 42.373654 | Q5: =IF(C5<>C4, "OSCILLATION", "--") -> -- | R5: ="SUM "&O1 -> SUM |E| * dt | S5: =SUM(O680:O1476) -> 259.7695 | T5: Total Integral Absolute Error (IAE)
A6: 1.7646157e+09 | B6: 46.645927 | C6: 20 | D6: 0 | E6: 0 | F6: 0 | G6: 20 | H6: 30 | I6: 20 | J6: 30 | K6: 0 | L6: STOPPED | M6: =A6-A5 -> 0.050719976 | N6: =C6-B6 -> -26.645927 | O6: =ABS(N6)*M6 -> 1.3514808 | P6: =N6^2 * M6 -> 36.01146 | Q6: =IF(C6<>C5, "OSCILLATION", "--") -> -- | R6: ="SUM "&P1 -> SUM E^2 * dt | S6: =SUM(P680:P1476) -> 2880.521 | T6: Total Integral Squared Error (ISE)
A7: 1.7646157e+09 | B7: 47.034371 | C7: 20 | D7: 0 | E7: 0 | F7: 0 | G7: 20 | H7: 30 | I7: 20 | J7: 30 | K7: 0 | L7: STOPPED | M7: =A7-A6 -> 0.049770117 | N7: =C7-B7 -> -27.034371 | O7: =ABS(N7)*M7 -> 1.3455038 | P7: =N7^2 * M7 -> 36.374849 | Q7: =IF(C7<>C6, "OSCILLATION", "--") -> --
A8: 1.7646157e+09 | B8: 48.6781 | C8: 20 | D8: 0 | E8: 0 | F8: 0 | G8: 20 | H8: 30 | I8: 20 | J8: 30 | K8: 0 | L8: STOPPED | M8: =A8-A7 -> 0.05050993 | N8: =C8-B8 -> -28.6781 | O8: =ABS(N8)*M8 -> 1.4485288 | P8: =N8^2 * M8 -> 41.541054 | Q8: =IF(C8<>C7, "OSCILLATION", "--") -> --
A9: 1.7646157e+09 | B9: 47.65588 | C9: 20 | D9: 0 | E9: 0 | F9: 0 | G9: 20 | H9: 30 | I9: 20 | J9: 30 | K9: 0 | L9: STOPPED | M9: =A9-A8 -> 0.049220085 | N9: =C9-B9 -> -27.65588 | O9: =ABS(N9)*M9 -> 1.3612248 | P9: =N9^2 * M9 -> 37.64587 | Q9: =IF(C9<>C8, "OSCILLATION", "--") -> -- | R9: OSCILLATION | S9: A->B
A10: 1.7646157e+09 | B10: 48.052502 | C10: 20 | D10: 0 | E10: 0 | F10: 0 | G10: 20 | H10: 30 | I10: 20 | J10: 30 | K10: 0 | L10: STOPPED | M10: =A10-A9 -> 0.050780058 | N10: =C10-B10 -> -28.052502 | O10: =ABS(N10)*M10 -> 1.4245077 | P10: =N10^2 * M10 -> 39.961004 | Q10: =IF(C10<>C9, "OSCILLATION", "--") -> -- | R10: Rows: | S10: 1078:1476
A11: 1.7646157e+09 | B11: 47.668147 | C11: 20 | D11: 0 | E11: 0 | F11: 0 | G11: 20 | H11: 30 | I11: 20 | J11: 30 | K11: 0 | L11: STOPPED | M11: =A11-A10 -> 0.05080986 | N11: =C11-B11 -> -27.668147 | O11: =ABS(N11)*M11 -> 1.4058147 | P11: =N11^2 * M11 -> 38.896288 | Q11: =IF(C11<>C10, "OSCILLATION", "--") -> -- | R11: SP_new | S11: =30 -> 30
A12: 1.7646157e+09 | B12: 47.880769 | C12: 20 | D12: 0 | E12: 0 | F12: 0 | G12: 20 | H12: 30 | I12: 20 | J12: 30 | K12: 0 | L12: STOPPED | M12: =A12-A11 -> 0.049279928 | N12: =C12-B12 -> -27.880769 | O12: =ABS(N12)*M12 -> 1.3739623 | P12: =N12^2 * M12 -> 38.307125 | Q12: =IF(C12<>C11, "OSCILLATION", "--") -> -- | R12: PV_peak | S12: =_xlfn.MAXIFS(B1078:B1476, B1078:B1476, "<60") -> 45.480597
A13: 1.7646157e+09 | B13: 48.068857 | C13: 20 | D13: 0 | E13: 0 | F13: 0 | G13: 20 | H13: 30 | I13: 20 | J13: 30 | K13: 0 | L13: STOPPED | M13: =A13-A12 -> 0.050370216 | N13: =C13-B13 -> -28.068857 | O13: =ABS(N13)*M13 -> 1.4138344 | P13: =N13^2 * M13 -> 39.684716 | Q13: =IF(C13<>C12, "OSCILLATION", "--") -> -- | R13: Overshoot (%) | S13: =(ABS(S12-S11)/S11)*100 -> 51.60199
A14: 1.7646157e+09 | B14: 47.631347 | C14: 20 | D14: 0 | E14: 0 | F14: 0 | G14: 20 | H14: 30 | I14: 20 | J14: 30 | K14: 0 | L14: STOPPED | M14: =A14-A13 -> 0.050989866 | N14: =C14-B14 -> -27.631347 | O14: =ABS(N14)*M14 -> 1.4089187 | P14: =N14^2 * M14 -> 38.930322 | Q14: =IF(C14<>C13, "OSCILLATION", "--") -> --
A15: 1.7646157e+09 | B15: 47.259259 | C15: 20 | D15: 0 | E15: 0 | F15: 0 | G15: 20 | H15: 30 | I15: 20 | J15: 30 | K15: 0 | L15: STOPPED | M15: =A15-A14 -> 0.050029993 | N15: =C15-B15 -> -27.259259 | O15: =ABS(N15)*M15 -> 1.3637805 | P15: =N15^2 * M15 -> 37.175648 | Q15: =IF(C15<>C14, "OSCILLATION", "--") -> --
A16: 1.7646157e+09 | B16: 45.57873 | C16: 20 | D16: 0 | E16: 0 | F16: 0 | G16: 20 | H16: 30 | I16: 20 | J16: 30 | K16: 0 | L16: STOPPED | M16: =A16-A15 -> 0.054170132 | N16: =C16-B16 -> -25.57873 | O16: =ABS(N16)*M16 -> 1.3856032 | P16: =N16^2 * M16 -> 35.44197 | Q16: =IF(C16<>C15, "OSCILLATION", "--") -> -- | R16: Fall Time: | S16: =S21-S20 -> 2.8110001
A17: 1.7646157e+09 | B17: 46.641839 | C17: 20 | D17: 0 | E17: 0 | F17: 0 | G17: 20 | H17: 30 | I17: 20 | J17: 30 | K17: 0 | L17: STOPPED | M17: =A17-A16 -> 0.046000004 | N17: =C17-B17 -> -26.641839 | O17: =ABS(N17)*M17 -> 1.2255247 | P17: =N17^2 * M17 -> 32.650231 | Q17: =IF(C17<>C16, "OSCILLATION", "--") -> -- | R17: Total Change (cm) | S17: =30-20 -> 10
A18: 1.7646157e+09 | B18: 47.079349 | C18: 20 | D18: 0 | E18: 0 | F18: 0 | G18: 20 | H18: 30 | I18: 20 | J18: 30 | K18: 0 | L18: STOPPED | M18: =A18-A17 -> 0.049849987 | N18: =C18-B18 -> -27.079349 | O18: =ABS(N18)*M18 -> 1.3499052 | P18: =N18^2 * M18 -> 36.554553 | Q18: =IF(C18<>C17, "OSCILLATION", "--") -> -- | R18: 10% Point (PV_10) (cm) | S18: =20+(10*0.1) -> 21
A19: 1.7646157e+09 | B19: 47.843969 | C19: 20 | D19: 0 | E19: 0 | F19: 0 | G19: 20 | H19: 30 | I19: 20 | J19: 30 | K19: 0 | L19: STOPPED | M19: =A19-A18 -> 0.051139832 | N19: =C19-B19 -> -27.843969 | O19: =ABS(N19)*M19 -> 1.4239359 | P19: =N19^2 * M19 -> 39.648026 | Q19: =IF(C19<>C18, "OSCILLATION", "--") -> -- | R19: 90% Point (PV_90) (cm) | S19: =20+(10*0.9) -> 29
A20: 1.7646157e+09 | B20: 47.672236 | C20: 20 | D20: 0 | E20: 0 | F20: 0 | G20: 20 | H20: 30 | I20: 20 | J20: 30 | K20: 0 | L20: STOPPED | M20: =A20-A19 -> 0.049710035 | N20: =C20-B20 -> -27.672236 | O20: =ABS(N20)*M20 -> 1.3755878 | P20: =N20^2 * M20 -> 38.065591 | Q20: =IF(C20<>C19, "OSCILLATION", "--") -> -- | R20: Time at 10% | S20: =A1105 -> 1.7646157e+09 | T20: Row 1105 | U20: (First row after setpoint change where distance ≥ 21)
A21: 1.7646157e+09 | B21: 47.688591 | C21: 20 | D21: 0 | E21: 0 | F21: 0 | G21: 20 | H21: 30 | I21: 20 | J21: 30 | K21: 0 | L21: STOPPED | M21: =A21-A20 -> 0.051280022 | N21: =C21-B21 -> -27.688591 | O21: =ABS(N21)*M21 -> 1.4198716 | P21: =N21^2 * M21 -> 39.314244 | Q21: =IF(C21<>C20, "OSCILLATION", "--") -> -- | R21: Time at 90% | S21: =A1161 -> 1.7646157e+09 | T21: Row 1161 | U21: (First row after setpoint change where distance ≥ 29)
A22: 1.7646157e+09 | B22: 46.883082 | C22: 20 | D22: 0 | E22: 0 | F22: 0 | G22: 20 | H22: 30 | I22: 20 | J22: 30 | K22: 0 | L22: STOPPED | M22: =A22-A21 -> 0.0488801 | N22: =C22-B22 -> -26.883082 | O22: =ABS(N22)*M22 -> 1.3140478 | P22: =N22^2 * M22 -> 35.325654 | Q22: =IF(C22<>C21, "OSCILLATION", "--") -> --
A23: 1.7646157e+09 | B23: 47.888947 | C23: 20 | D23: 0 | E23: 0 | F23: 0 | G23: 20 | H23: 30 | I23: 20 | J23: 30 | K23: 0 | L23: STOPPED | M23: =A23-A22 -> 0.050029993 | N23: =C23-B23 -> -27.888947 | O23: =ABS(N23)*M23 -> 1.3952838 | P23: =N23^2 * M23 -> 38.912995 | Q23: =IF(C23<>C22, "OSCILLATION", "--") -> --
A24: 1.7646157e+09 | B24: 47.664058 | C24: 20 | D24: 0 | E24: 0 | F24: 0 | G24: 20 | H24: 30 | I24: 20 | J24: 30 | K24: 0 | L24: STOPPED | M24: =A24-A23 -> 0.050019979 | N24: =C24-B24 -> -27.664058 | O24: =ABS(N24)*M24 -> 1.3837556 | P24: =N24^2 * M24 -> 38.280296 | Q24: =IF(C24<>C23, "OSCILLATION", "--") -> -- | R24: OSCILLATION | S24: B->A
A25: 1.7646157e+09 | B25: 47.071171 | C25: 20 | D25: 0 | E25: 0 | F25: 0 | G25: 20 | H25: 30 | I25: 20 | J25: 30 | K25: 0 | L25: STOPPED | M25: =A25-A24 -> 0.050379992 | N25: =C25-B25 -> -27.071171 | O25: =ABS(N25)*M25 -> 1.3638454 | P25: =N25^2 * M25 -> 36.920891 | Q25: =IF(C25<>C24, "OSCILLATION", "--") -> -- | R25: Rows: | S25: 680:1077
A26: 1.7646157e+09 | B26: 47.25517 | C26: 20 | D26: 0 | E26: 0 | F26: 0 | G26: 20 | H26: 30 | I26: 20 | J26: 30 | K26: 0 | L26: STOPPED | M26: =A26-A25 -> 0.050449848 | N26: =C26-B26 -> -27.25517 | O26: =ABS(N26)*M26 -> 1.3750192 | P26: =N26^2 * M26 -> 37.476383 | Q26: =IF(C26<>C25, "OSCILLATION", "--") -> -- | R26: SP_new | S26: =20 -> 20
A27: 1.7646157e+09 | B27: 47.868502 | C27: 20 | D27: 0 | E27: 0 | F27: 0 | G27: 20 | H27: 30 | I27: 20 | J27: 30 | K27: 0 | L27: STOPPED | M27: =A27-A26 -> 0.050029993 | N27: =C27-B27 -> -27.868502 | O27: =ABS(N27)*M27 -> 1.394261 | P27: =N27^2 * M27 -> 38.855965 | Q27: =IF(C27<>C26, "OSCILLATION", "--") -> -- | R27: PV_valley | S27: =MIN(B680:B1077) -> 13.080323
A28: 1.7646157e+09 | B28: 46.662283 | C28: 20 | D28: 0 | E28: 0 | F28: 0 | G28: 20 | H28: 30 | I28: 20 | J28: 30 | K28: 0 | L28: STOPPED | M28: =A28-A27 -> 0.050840139 | N28: =C28-B28 -> -26.662283 | O28: =ABS(N28)*M28 -> 1.3555142 | P28: =N28^2 * M28 -> 36.141103 | Q28: =IF(C28<>C27, "OSCILLATION", "--") -> -- | R28: Overshoot (%) | S28: =(ABS(S27-S26)/S26)*100 -> 34.598386
A29: 1.7646157e+09 | B29: 47.030282 | C29: 20 | D29: 0 | E29: 0 | F29: 0 | G29: 20 | H29: 30 | I29: 20 | J29: 30 | K29: 0 | L29: STOPPED | M29: =A29-A28 -> 0.051440001 | N29: =C29-B29 -> -27.030282 | O29: =ABS(N29)*M29 -> 1.3904377 | P29: =N29^2 * M29 -> 37.583924 | Q29: =IF(C29<>C28, "OSCILLATION", "--") -> --
A30: 1.7646157e+09 | B30: 47.230637 | C30: 20 | D30: 0 | E30: 0 | F30: 0 | G30: 20 | H30: 30 | I30: 20 | J30: 30 | K30: 0 | L30: STOPPED | M30: =A30-A29 -> 0.048449993 | N30: =C30-B30 -> -27.230637 | O30: =ABS(N30)*M30 -> 1.3193242 | P30: =N30^2 * M30 -> 35.926038 | Q30: =IF(C30<>C29, "OSCILLATION", "--") -> --
A31: 1.7646157e+09 | B31: 48.894811 | C31: 20 | D31: 0 | E31: 0 | F31: 0 | G31: 20 | H31: 30 | I31: 20 | J31: 30 | K31: 0 | L31: STOPPED | M31: =A31-A30 -> 0.05140996 | N31: =C31-B31 -> -28.894811 | O31: =ABS(N31)*M31 -> 1.4854811 | P31: =N31^2 * M31 -> 42.922694 | Q31: =IF(C31<>C30, "OSCILLATION", "--") -> -- | R31: Rise Time: | S31: =S36-S35 -> 3.61255
A32: 1.7646157e+09 | B32: 47.071171 | C32: 20 | D32: 0 | E32: 0 | F32: 0 | G32: 20 | H32: 30 | I32: 20 | J32: 30 | K32: 0 | L32: STOPPED | M32: =A32-A31 -> 0.049060106 | N32: =C32-B32 -> -27.071171 | O32: =ABS(N32)*M32 -> 1.3281145 | P32: =N32^2 * M32 -> 35.953615 | Q32: =IF(C32<>C31, "OSCILLATION", "--") -> -- | R32: Total Change (cm) | S32: =30-20 -> 10
A33: 1.7646157e+09 | B33: 47.054815 | C33: 20 | D33: 0 | E33: 0 | F33: 0 | G33: 20 | H33: 30 | I33: 20 | J33: 30 | K33: 0 | L33: STOPPED | M33: =A33-A32 -> 0.049690008 | N33: =C33-B33 -> -27.054815 | O33: =ABS(N33)*M33 -> 1.344354 | P33: =N33^2 * M33 -> 36.371249 | Q33: =IF(C33<>C32, "OSCILLATION", "--") -> -- | R33: 10% Point (PV_10) (cm) | S33: =30-(10*0.1) -> 29
A34: 1.7646157e+09 | B34: 48.289657 | C34: 20 | D34: 0 | E34: 0 | F34: 0 | G34: 20 | H34: 30 | I34: 20 | J34: 30 | K34: 0 | L34: STOPPED | M34: =A34-A33 -> 0.050939798 | N34: =C34-B34 -> -28.289657 | O34: =ABS(N34)*M34 -> 1.4410694 | P34: =N34^2 * M34 -> 40.767359 | Q34: =IF(C34<>C33, "OSCILLATION", "--") -> -- | R34: 90% Point (PV_90) (cm) | S34: =30-(10*0.9) -> 21
A35: 1.7646157e+09 | B35: 44.940865 | C35: 20 | D35: 0 | E35: 0 | F35: 0 | G35: 20 | H35: 30 | I35: 20 | J35: 30 | K35: 0 | L35: STOPPED | M35: =A35-A34 -> 0.04975009 | N35: =C35-B35 -> -24.940865 | O35: =ABS(N35)*M35 -> 1.2408103 | P35: =N35^2 * M35 -> 30.946882 | Q35: =IF(C35<>C34, "OSCILLATION", "--") -> -- | R35: Time at 10% | S35: =A720 -> 1.7646157e+09 | T35: Row 720 | U35: (First row after setpoint change where distance ≤ 29)
A36: 1.7646157e+09 | B36: 48.072946 | C36: 20 | D36: 0 | E36: 0 | F36: 0 | G36: 20 | H36: 30 | I36: 20 | J36: 30 | K36: 0 | L36: STOPPED | M36: =A36-A35 -> 0.049950123 | N36: =C36-B36 -> -28.072946 | O36: =ABS(N36)*M36 -> 1.4022471 | P36: =N36^2 * M36 -> 39.365207 | Q36: =IF(C36<>C35, "OSCILLATION", "--") -> -- | R36: Time at 90% | S36: =A792 -> 1.7646157e+09 | T36: Row 792 | U36: (First row after setpoint change where distance ≤ 21)
A37: 1.7646157e+09 | B37: 47.259259 | C37: 20 | D37: 0 | E37: 0 | F37: 0 | G37: 20 | H37: 30 | I37: 20 | J37: 30 | K37: 0 | L37: STOPPED | M37: =A37-A36 -> 0.050529957 | N37: =C37-B37 -> -27.259259 | O37: =ABS(N37)*M37 -> 1.3774092 | P37: =N37^2 * M37 -> 37.547154 | Q37: =IF(C37<>C36, "OSCILLATION", "--") -> --
A38: 1.7646157e+09 | B38: 46.441483 | C38: 20 | D38: 0 | E38: 0 | F38: 0 | G38: 20 | H38: 30 | I38: 20 | J38: 30 | K38: 0 | L38: STOPPED | M38: =A38-A37 -> 0.049999952 | N38: =C38-B38 -> -26.441483 | O38: =ABS(N38)*M38 -> 1.3220729 | P38: =N38^2 * M38 -> 34.957569 | Q38: =IF(C38<>C37, "OSCILLATION", "--") -> --
A39: 1.7646157e+09 | B39: 47.058904 | C39: 20 | D39: 0 | E39: 0 | F39: 0 | G39: 20 | H39: 30 | I39: 20 | J39: 30 | K39: 0 | L39: STOPPED | M39: =A39-A38 -> 0.049570084 | N39: =C39-B39 -> -27.058904 | O39: =ABS(N39)*M39 -> 1.3413121 | P39: =N39^2 * M39 -> 36.294437 | Q39: =IF(C39<>C38, "OSCILLATION", "--") -> --
A40: 1.7646157e+09 | B40: 47.050726 | C40: 20 | D40: 0 | E40: 0 | F40: 0 | G40: 20 | H40: 30 | I40: 20 | J40: 30 | K40: 0 | L40: STOPPED | M40: =A40-A39 -> 0.051329851 | N40: =C40-B40 -> -27.050726 | O40: =ABS(N40)*M40 -> 1.3885098 | P40: =N40^2 * M40 -> 37.560198 | Q40: =IF(C40<>C39, "OSCILLATION", "--") -> --
...

Sheet sensor_log_baseline_tc
A1: timestamp | B1: distance | C1: setpoint | D1: duty | E1: delay_ms | F1: loss_rate | G1: osc_a | H1: osc_b | I1: osc_period | J1: next_setpoint | K1: switch_in | L1: pid_status | M1: Time Step (dt) | N1: Error (E) | O1: |E| * dt | P1: E^2 * dt
A2: 1.7646166e+09 | B2: 48.068857 | C2: 20 | D2: 0 | E2: 0 | F2: 0 | G2: 20 | H2: 30 | I2: 20 | J2: 30 | K2: 0 | L2: STOPPED | M2: (Time Between Samples) | N2: (Instantaneous Tracking Error) | O2: (Instantaneous Area under the Absolute Error Curve) | P2: (Instantaneous Area under the Squared Error Curve) | R2: SUM dt | S2: =SUM(M307:M1104) -> 40.04478
A3: 1.7646166e+09 | B3: 47.696769 | C3: 20 | D3: 0 | E3: 0 | F3: 0 | G3: 20 | H3: 30 | I3: 20 | J3: 30 | K3: 0 | L3: STOPPED | M3: =A3-A2 -> 0.049770117 | N3: =C3-B3 -> -27.696769 | O3: =ABS(N3)*M3 -> 1.3784714 | P3: =N3^2 * M3 -> 38.179205 | Q3: =IF(C3<>C2, "OSCILLATION", "--") -> -- | R3: SUM E | S3: =SUM(N307:N1104) -> -1366.461
A4: 1.7646166e+09 | B4: 48.081124 | C4: 20 | D4: 0 | E4: 0 | F4: 0 | G4: 20 | H4: 30 | I4: 20 | J4: 30 | K4: 0 | L4: STOPPED | M4: =A4-A3 -> 0.049249887 | N4: =C4-B4 -> -28.081124 | O4: =ABS(N4)*M4 -> 1.3829922 | P4: =N4^2 * M4 -> 38.835975 | Q4: =IF(C4<>C3, "OSCILLATION", "--") -> -- | R4: ="SUM "&O1 -> SUM |E| * dt | S4: =SUM(O307:O1104) -> 93.833179 | T4: Total Integral Absolute Error (IAE)
A5: 1.7646166e+09 | B5: 47.733569 | C5: 20 | D5: 0 | E5: 0 | F5: 0 | G5: 20 | H5: 30 | I5: 20 | J5: 30 | K5: 0 | L5: STOPPED | M5: =A5-A4 -> 0.050529957 | N5: =C5-B5 -> -27.733569 | O5: =ABS(N5)*M5 -> 1.4013761 | P5: =N5^2 * M5 -> 38.86516 | Q5: =IF(C5<>C4, "OSCILLATION", "--") -> -- | R5: ="SUM "&P1 -> SUM E^2 * dt | S5: =SUM(P307:P1104) -> 561.79674 | T5: Total Integral Squared Error (ISE)
A6: 1.7646166e+09 | B6: 48.052502 | C6: 20 | D6: 0 | E6: 0 | F6: 0 | G6: 20 | H6: 30 | I6: 20 | J6: 30 | K6: 0 | L6: STOPPED | M6: =A6-A5 -> 0.049580097 | N6: =C6-B6 -> -28.052502 | O6: =ABS(N6)*M6 -> 1.3908458 | P6: =N6^2 * M6 -> 39.016703 | Q6: =IF(C6<>C5, "OSCILLATION", "--") -> --
A7: 1.7646166e+09 | B7: 48.101568 | C7: 20 | D7: 0 | E7: 0 | F7: 0 | G7: 20 | H7: 30 | I7: 20 | J7: 30 | K7: 0 | L7: STOPPED | M7: =A7-A6 -> 0.051520109 | N7: =C7-B7 -> -28.101568 | O7: =ABS(N7)*M7 -> 1.4477959 | P7: =N7^2 * M7 -> 40.685334 | Q7: =IF(C7<>C6, "OSCILLATION", "--") -> -- | R7: OSCILLATION | S7: A->B
A8: 1.7646166e+09 | B8: 48.236501 | C8: 20 | D8: 0 | E8: 0 | F8: 0 | G8: 20 | H8: 30 | I8: 20 | J8: 30 | K8: 0 | L8: STOPPED | M8: =A8-A7 -> 0.050619841 | N8: =C8-B8 -> -28.236501 | O8: =ABS(N8)*M8 -> 1.4293272 | P8: =N8^2 * M8 -> 40.359199 | Q8: =IF(C8<>C7, "OSCILLATION", "--") -> -- | R8: Rows: | S8: 307:705
A9: 1.7646166e+09 | B9: 47.43917 | C9: 20 | D9: 0 | E9: 0 | F9: 0 | G9: 20 | H9: 30 | I9: 20 | J9: 30 | K9: 0 | L9: STOPPED | M9: =A9-A8 -> 0.049910069 | N9: =C9-B9 -> -27.43917 | O9: =ABS(N9)*M9 -> 1.3694908 | P9: =N9^2 * M9 -> 37.577692 | Q9: =IF(C9<>C8, "OSCILLATION", "--") -> -- | R9: SP_new | S9: =30 -> 30
A10: 1.7646166e+09 | B10: 48.056591 | C10: 20 | D10: 0 | E10: 0 | F10: 0 | G10: 20 | H10: 30 | I10: 20 | J10: 30 | K10: 0 | L10: STOPPED | M10: =A10-A9 -> 0.05024004 | N10: =C10-B10 -> -28.056591 | O10: =ABS(N10)*M10 -> 1.4095642 | P10: =N10^2 * M10 -> 39.547566 | Q10: =IF(C10<>C9, "OSCILLATION", "--") -> -- | R10: PV_peak | S10: =_xlfn.MAXIFS(B307:B705, B307:B705, "<60") -> 40.005589
A11: 1.7646166e+09 | B11: 49.671698 | C11: 20 | D11: 0 | E11: 0 | F11: 0 | G11: 20 | H11: 30 | I11: 20 | J11: 30 | K11: 0 | L11: STOPPED | M11: =A11-A10 -> 0.051039934 | N11: =C11-B11 -> -29.671698 | O11: =ABS(N11)*M11 -> 1.5144415 | P11: =N11^2 * M11 -> 44.93605 | Q11: =IF(C11<>C10, "OSCILLATION", "--") -> -- | R11: Overshoot (%) | S11: =(ABS(S10-S9)/S9)*100 -> 33.351962
A12: 1.7646166e+09 | B12: 47.062993 | C12: 20 | D12: 0 | E12: 0 | F12: 0 | G12: 20 | H12: 30 | I12: 20 | J12: 30 | K12: 0 | L12: STOPPED | M12: =A12-A11 -> 0.049649954 | N12: =C12-B12 -> -27.062993 | O12: =ABS(N12)*M12 -> 1.3436764 | P12: =N12^2 * M12 -> 36.363904 | Q12: =IF(C12<>C11, "OSCILLATION", "--") -> --
A13: 1.7646166e+09 | B13: 48.097479 | C13: 20 | D13: 0 | E13: 0 | F13: 0 | G13: 20 | H13: 30 | I13: 20 | J13: 30 | K13: 0 | L13: STOPPED | M13: =A13-A12 -> 0.052160025 | N13: =C13-B13 -> -28.097479 | O13: =ABS(N13)*M13 -> 1.4655652 | P13: =N13^2 * M13 -> 41.178688 | Q13: =IF(C13<>C12, "OSCILLATION", "--") -> -- | R13: Fall Time: | S13: =S18-S17 -> 1.4051402
A14: 1.7646166e+09 | B14: 49.716675 | C14: 20 | D14: 0 | E14: 0 | F14: 0 | G14: 20 | H14: 30 | I14: 20 | J14: 30 | K14: 0 | L14: STOPPED | M14: =A14-A13 -> 0.048939943 | N14: =C14-B14 -> -29.716675 | O14: =ABS(N14)*M14 -> 1.4543324 | P14: =N14^2 * M14 -> 43.217924 | Q14: =IF(C14<>C13, "OSCILLATION", "--") -> -- | R14: Total Change (cm) | S14: =30-20 -> 10
A15: 1.7646166e+09 | B15: 48.089302 | C15: 20 | D15: 0 | E15: 0 | F15: 0 | G15: 20 | H15: 30 | I15: 20 | J15: 30 | K15: 0 | L15: STOPPED | M15: =A15-A14 -> 0.050080061 | N15: =C15-B15 -> -28.089302 | O15: =ABS(N15)*M15 -> 1.4067139 | P15: =N15^2 * M15 -> 39.513612 | Q15: =IF(C15<>C14, "OSCILLATION", "--") -> -- | R15: 10% Point (PV_10) (cm) | S15: =20+(10*0.1) -> 21
A16: 1.7646166e+09 | B16: 48.077035 | C16: 20 | D16: 0 | E16: 0 | F16: 0 | G16: 20 | H16: 30 | I16: 20 | J16: 30 | K16: 0 | L16: STOPPED | M16: =A16-A15 -> 0.049910069 | N16: =C16-B16 -> -28.077035 | O16: =ABS(N16)*M16 -> 1.4013267 | P16: =N16^2 * M16 -> 39.3451 | Q16: =IF(C16<>C15, "OSCILLATION", "--") -> -- | R16: 90% Point (PV_90) (cm) | S16: =20+(10*0.9) -> 29
A17: 1.7646166e+09 | B17: 47.668147 | C17: 20 | D17: 0 | E17: 0 | F17: 0 | G17: 20 | H17: 30 | I17: 20 | J17: 30 | K17: 0 | L17: STOPPED | M17: =A17-A16 -> 0.049520016 | N17: =C17-B17 -> -27.668147 | O17: =ABS(N17)*M17 -> 1.3701271 | P17: =N17^2 * M17 -> 37.908878 | Q17: =IF(C17<>C16, "OSCILLATION", "--") -> -- | R17: Time at 10% | S17: =A310 -> 1.7646166e+09 | T17: Row 310 | U17: (First row after setpoint change where distance ≥ 21)
A18: 1.7646166e+09 | B18: 48.064768 | C18: 20 | D18: 0 | E18: 0 | F18: 0 | G18: 20 | H18: 30 | I18: 20 | J18: 30 | K18: 0 | L18: STOPPED | M18: =A18-A17 -> 0.050209999 | N18: =C18-B18 -> -28.064768 | O18: =ABS(N18)*M18 -> 1.409132 | P18: =N18^2 * M18 -> 39.546963 | Q18: =IF(C18<>C17, "OSCILLATION", "--") -> -- | R18: Time at 90% | S18: =A338 -> 1.7646166e+09 | T18: Row 338 | U18: (First row after setpoint change where distance ≥ 29)
A19: 1.7646166e+09 | B19: 48.077035 | C19: 20 | D19: 0 | E19: 0 | F19: 0 | G19: 20 | H19: 30 | I19: 20 | J19: 30 | K19: 0 | L19: STOPPED | M19: =A19-A18 -> 0.051209927 | N19: =C19-B19 -> -28.077035 | O19: =ABS(N19)*M19 -> 1.4378229 | P19: =N19^2 * M19 -> 40.369804 | Q19: =IF(C19<>C18, "OSCILLATION", "--") -> --
A20: 1.7646166e+09 | B20: 48.064768 | C20: 20 | D20: 0 | E20: 0 | F20: 0 | G20: 20 | H20: 30 | I20: 20 | J20: 30 | K20: 0 | L20: STOPPED | M20: =A20-A19 -> 0.05437994 | N20: =C20-B20 -> -28.064768 | O20: =ABS(N20)*M20 -> 1.5261604 | P20: =N20^2 * M20 -> 42.831339 | Q20: =IF(C20<>C19, "OSCILLATION", "--") -> -- | R20: OSCILLATION | S20: B->A
A21: 1.7646166e+09 | B21: 48.068857 | C21: 20 | D21: 0 | E21: 0 | F21: 0 | G21: 20 | H21: 30 | I21: 20 | J21: 30 | K21: 0 | L21: STOPPED | M21: =A21-A20 -> 0.044990063 | N21: =C21-B21 -> -28.068857 | O21: =ABS(N21)*M21 -> 1.2628196 | P21: =N21^2 * M21 -> 35.445904 | Q21: =IF(C21<>C20, "OSCILLATION", "--") -> -- | R21: Rows: | S21: 706:1104
A22: 1.7646166e+09 | B22: 48.064768 | C22: 20 | D22: 0 | E22: 0 | F22: 0 | G22: 20 | H22: 30 | I22: 20 | J22: 30 | K22: 0 | L22: STOPPED | M22: =A22-A21 -> 0.05005002 | N22: =C22-B22 -> -28.064768 | O22: =ABS(N22)*M22 -> 1.4046422 | P22: =N22^2 * M22 -> 39.420959 | Q22: =IF(C22<>C21, "OSCILLATION", "--") -> -- | R22: SP_new | S22: =20 -> 20
A23: 1.7646166e+09 | B23: 48.085213 | C23: 20 | D23: 0 | E23: 0 | F23: 0 | G23: 20 | H23: 30 | I23: 20 | J23: 30 | K23: 0 | L23: STOPPED | M23: =A23-A22 -> 0.050080061 | N23: =C23-B23 -> -28.085213 | O23: =ABS(N23)*M23 -> 1.4065092 | P23: =N23^2 * M23 -> 39.502109 | Q23: =IF(C23<>C22, "OSCILLATION", "--") -> -- | R23: PV_valley | S23: =MIN(B706:B1104) -> 17.733467
A24: 1.7646166e+09 | B24: 48.048413 | C24: 20 | D24: 0 | E24: 0 | F24: 0 | G24: 20 | H24: 30 | I24: 20 | J24: 30 | K24: 0 | L24: STOPPED | M24: =A24-A23 -> 0.050199986 | N24: =C24-B24 -> -28.048413 | O24: =ABS(N24)*M24 -> 1.4080299 | P24: =N24^2 * M24 -> 39.493004 | Q24: =IF(C24<>C23, "OSCILLATION", "--") -> -- | R24: Overshoot (%) | S24: =(ABS(S23-S22)/S22)*100 -> 11.332667
A25: 1.7646166e+09 | B25: 47.647703 | C25: 20 | D25: 0 | E25: 0 | F25: 0 | G25: 20 | H25: 30 | I25: 20 | J25: 30 | K25: 0 | L25: STOPPED | M25: =A25-A24 -> 0.050220013 | N25: =C25-B25 -> -27.647703 | O25: =ABS(N25)*M25 -> 1.388468 | P25: =N25^2 * M25 -> 38.38795 | Q25: =IF(C25<>C24, "OSCILLATION", "--") -> --
A26: 1.7646166e+09 | B26: 48.068857 | C26: 20 | D26: 0 | E26: 0 | F26: 0 | G26: 20 | H26: 30 | I26: 20 | J26: 30 | K26: 0 | L26: STOPPED | M26: =A26-A25 -> 0.050259829 | N26: =C26-B26 -> -28.068857 | O26: =ABS(N26)*M26 -> 1.410736 | P26: =N26^2 * M26 -> 39.597746 | Q26: =IF(C26<>C25, "OSCILLATION", "--") -> -- | R26: Rise Time: | S26: =S31-S30 -> 3.4122598
A27: 1.7646166e+09 | B27: 48.064768 | C27: 20 | D27: 0 | E27: 0 | F27: 0 | G27: 20 | H27: 30 | I27: 20 | J27: 30 | K27: 0 | L27: STOPPED | M27: =A27-A26 -> 0.051150084 | N27: =C27-B27 -> -28.064768 | O27: =ABS(N27)*M27 -> 1.4355152 | P27: =N27^2 * M27 -> 40.287403 | Q27: =IF(C27<>C26, "OSCILLATION", "--") -> -- | R27: Total Change (cm) | S27: =30-20 -> 10
A28: 1.7646166e+09 | B28: 48.077035 | C28: 20 | D28: 0 | E28: 0 | F28: 0 | G28: 20 | H28: 30 | I28: 20 | J28: 30 | K28: 0 | L28: STOPPED | M28: =A28-A27 -> 0.049459934 | N28: =C28-B28 -> -28.077035 | O28: =ABS(N28)*M28 -> 1.3886883 | P28: =N28^2 * M28 -> 38.99025 | Q28: =IF(C28<>C27, "OSCILLATION", "--") -> -- | R28: 10% Point (PV_10) (cm) | S28: =30-(10*0.1) -> 29
A29: 1.7646166e+09 | B29: 48.064768 | C29: 20 | D29: 0 | E29: 0 | F29: 0 | G29: 20 | H29: 30 | I29: 20 | J29: 30 | K29: 0 | L29: STOPPED | M29: =A29-A28 -> 0.049860001 | N29: =C29-B29 -> -28.064768 | O29: =ABS(N29)*M29 -> 1.3993094 | P29: =N29^2 * M29 -> 39.271293 | Q29: =IF(C29<>C28, "OSCILLATION", "--") -> -- | R29: 90% Point (PV_90) (cm) | S29: =30-(10*0.9) -> 21
A30: 1.7646166e+09 | B30: 48.085213 | C30: 20 | D30: 0 | E30: 0 | F30: 0 | G30: 20 | H30: 30 | I30: 20 | J30: 30 | K30: 0 | L30: STOPPED | M30: =A30-A29 -> 0.051110029 | N30: =C30-B30 -> -28.085213 | O30: =ABS(N30)*M30 -> 1.435436 | P30: =N30^2 * M30 -> 40.314527 | Q30: =IF(C30<>C29, "OSCILLATION", "--") -> -- | R30: Time at 10% | S30: =A736 -> 1.7646166e+09 | T30: Row 736 | U30: (First row after setpoint change where distance ≤ 29)
A31: 1.7646166e+09 | B31: 48.068857 | C31: 20 | D31: 0 | E31: 0 | F31: 0 | G31: 20 | H31: 30 | I31: 20 | J31: 30 | K31: 0 | L31: STOPPED | M31: =A31-A30 -> 0.049580097 | N31: =C31-B31 -> -28.068857 | O31: =ABS(N31)*M31 -> 1.3916567 | P31: =N31^2 * M31 -> 39.062212 | Q31: =IF(C31<>C30, "OSCILLATION", "--") -> -- | R31: Time at 90% | S31: =A804 -> 1.7646166e+09 | T31: Row 804 | U31: (First row after setpoint change where distance ≤ 21)
A32: 1.7646166e+09 | B32: 48.056591 | C32: 20 | D32: 0 | E32: 0 | F32: 0 | G32: 20 | H32: 30 | I32: 20 | J32: 30 | K32: 0 | L32: STOPPED | M32: =A32-A31 -> 0.049900055 | N32: =C32-B32 -> -28.056591 | O32: =ABS(N32)*M32 -> 1.4000254 | P32: =N32^2 * M32 -> 39.27994 | Q32: =IF(C32<>C31, "OSCILLATION", "--") -> --
A33: 1.7646166e+09 | B33: 48.20379 | C33: 20 | D33: 0 | E33: 0 | F33: 0 | G33: 20 | H33: 30 | I33: 20 | J33: 30 | K33: 0 | L33: STOPPED | M33: =A33-A32 -> 0.050459862 | N33: =C33-B33 -> -28.20379 | O33: =ABS(N33)*M33 -> 1.4231594 | P33: =N33^2 * M33 -> 40.138488 | Q33: =IF(C33<>C32, "OSCILLATION", "--") -> --
A34: 1.7646166e+09 | B34: 48.085213 | C34: 20 | D34: 0 | E34: 0 | F34: 0 | G34: 20 | H34: 30 | I34: 20 | J34: 30 | K34: 0 | L34: STOPPED | M34: =A34-A33 -> 0.049940109 | N34: =C34-B34 -> -28.085213 | O34: =ABS(N34)*M34 -> 1.4025786 | P34: =N34^2 * M34 -> 39.391718 | Q34: =IF(C34<>C33, "OSCILLATION", "--") -> --
A35: 1.7646166e+09 | B35: 48.077035 | C35: 20 | D35: 0 | E35: 0 | F35: 0 | G35: 20 | H35: 30 | I35: 20 | J35: 30 | K35: 0 | L35: STOPPED | M35: =A35-A34 -> 0.049949884 | N35: =C35-B35 -> -28.077035 | O35: =ABS(N35)*M35 -> 1.4024447 | P35: =N35^2 * M35 -> 39.376487 | Q35: =IF(C35<>C34, "OSCILLATION", "--") -> --
A36: 1.7646166e+09 | B36: 48.085213 | C36: 20 | D36: 0 | E36: 0 | F36: 0 | G36: 20 | H36: 30 | I36: 20 | J36: 30 | K36: 0 | L36: STOPPED | M36: =A36-A35 -> 0.051460028 | N36: =C36-B36 -> -28.085213 | O36: =ABS(N36)*M36 -> 1.4452658 | P36: =N36^2 * M36 -> 40.590598 | Q36: =IF(C36<>C35, "OSCILLATION", "--") -> --
A37: 1.7646166e+09 | B37: 48.02388 | C37: 20 | D37: 0 | E37: 0 | F37: 0 | G37: 20 | H37: 30 | I37: 20 | J37: 30 | K37: 0 | L37: STOPPED | M37: =A37-A36 -> 0.049350023 | N37: =C37-B37 -> -28.02388 | O37: =ABS(N37)*M37 -> 1.3829791 | P37: =N37^2 * M37 -> 38.75644 | Q37: =IF(C37<>C36, "OSCILLATION", "--") -> --
A38: 1.7646166e+09 | B38: 47.488236 | C38: 20 | D38: 0 | E38: 0 | F38: 0 | G38: 20 | H38: 30 | I38: 20 | J38: 30 | K38: 0 | L38: STOPPED | M38: =A38-A37 -> 0.050209999 | N38: =C38-B38 -> -27.488236 | O38: =ABS(N38)*M38 -> 1.3801843 | P38: =N38^2 * M38 -> 37.938833 | Q38: =IF(C38<>C37, "OSCILLATION", "--") -> --
A39: 1.7646166e+09 | B39: 48.109746 | C39: 20 | D39: 0 | E39: 0 | F39: 0 | G39: 20 | H39: 30 | I39: 20 | J39: 30 | K39: 0 | L39: STOPPED | M39: =A39-A38 -> 0.049979925 | N39: =C39-B39 -> -28.109746 | O39: =ABS(N39)*M39 -> 1.404923 | P39: =N39^2 * M39 -> 39.492029 | Q39: =IF(C39<>C38, "OSCILLATION", "--") -> --
A40: 1.7646166e+09 | B40: 48.072946 | C40: 20 | D40: 0 | E40: 0 | F40: 0 | G40: 20 | H40: 30 | I40: 20 | J40: 30 | K40: 0 | L40: STOPPED | M40: =A40-A39 -> 0.049880028 | N40: =C40-B40 -> -28.072946 | O40: =ABS(N40)*M40 -> 1.4002793 | P40: =N40^2 * M40 -> 39.309966 | Q40: =IF(C40<>C39, "OSCILLATION", "--") -> --
...

Sheet sensor_log_cpu_tc
A1: timestamp | B1: distance | C1: setpoint | D1: duty | E1: delay_ms | F1: loss_rate | G1: osc_a | H1: osc_b | I1: osc_period | J1: next_setpoint | K1: switch_in | L1: pid_status | M1: Time Step (dt) | N1: Error (E) | O1: |E| * dt | P1: E^2 * dt
A2: 1.7646171e+09 | B2: 47.880769 | C2: 20 | D2: 0 | E2: 0 | F2: 0 | G2: 20 | H2: 30 | I2: 20 | J2: 30 | K2: 0 | L2: STOPPED | M2: (Time Between Samples) | N2: (Instantaneous Tracking Error) | O2: (Instantaneous Area under the Absolute Error Curve) | P2: (Instantaneous Area under the Squared Error Curve)
A3: 1.7646171e+09 | B3: 48.653567 | C3: 20 | D3: 0 | E3: 0 | F3: 0 | G3: 20 | H3: 30 | I3: 20 | J3: 30 | K3: 0 | L3: STOPPED | M3: =A3-A2 -> 0.045650005 | N3: =C3-B3 -> -28.653567 | O3: =ABS(N3)*M3 -> 1.3080355 | P3: =N3^2 * M3 -> 37.479882 | Q3: =IF(C3<>C2, "OSCILLATION", "--") -> -- | R3: SUM dt | S3: =SUM(M812:M1609) -> 40.02517
A4: 1.7646171e+09 | B4: 47.651792 | C4: 20 | D4: 0 | E4: 0 | F4: 0 | G4: 20 | H4: 30 | I4: 20 | J4: 30 | K4: 0 | L4: STOPPED | M4: =A4-A3 -> 0.051939964 | N4: =C4-B4 -> -27.651792 | O4: =ABS(N4)*M4 -> 1.4362331 | P4: =N4^2 * M4 -> 39.714417 | Q4: =IF(C4<>C3, "OSCILLATION", "--") -> -- | R4: SUM E | S4: =SUM(N812:N1609) -> -1243.304
A5: 1.7646171e+09 | B5: 47.267437 | C5: 20 | D5: 0 | E5: 0 | F5: 0 | G5: 20 | H5: 30 | I5: 20 | J5: 30 | K5: 0 | L5: STOPPED | M5: =A5-A4 -> 0.048280001 | N5: =C5-B5 -> -27.267437 | O5: =ABS(N5)*M5 -> 1.3164719 | P5: =N5^2 * M5 -> 35.896814 | Q5: =IF(C5<>C4, "OSCILLATION", "--") -> -- | R5: ="SUM "&O1 -> SUM |E| * dt | S5: =SUM(O812:O1609) -> 93.003131 | T5: Total Integral Absolute Error (IAE)
A6: 1.7646171e+09 | B6: 48.301923 | C6: 20 | D6: 0 | E6: 0 | F6: 0 | G6: 20 | H6: 30 | I6: 20 | J6: 30 | K6: 0 | L6: STOPPED | M6: =A6-A5 -> 0.050230026 | N6: =C6-B6 -> -28.301923 | O6: =ABS(N6)*M6 -> 1.4216063 | P6: =N6^2 * M6 -> 40.234194 | Q6: =IF(C6<>C5, "OSCILLATION", "--") -> -- | R6: ="SUM "&P1 -> SUM E^2 * dt | S6: =SUM(P812:P1609) -> 587.16069 | T6: Total Integral Squared Error (ISE)
